Workbook
Name Slicer_REGION_PRODUCT_NAME: #N/A
Name Slicer_SALESPERSON: #N/A

Sheet CHART 1
A3: Row Labels | B3: Sum of TOTAL INCOME
A4: Apr | B4: 2040
A5: May | B5: 5190
A6: Jun | B6: 2540
A7: Aug | B7: 8700
A8: Sep | B8: 2280
A9: Grand Total | B9: 20750

Sheet Sheet2
A3: Row Labels | B3: Sum of TOTAL INCOME
A4: AMAN | B4: 4110
A5: AMIT | B5: 4150
A6: PRIYA | B6: 3200
A7: SAM | B7: 4000
A8: SUMIT | B8: 5290
A9: Grand Total | B9: 20750

Sheet Sheet3
A3: Row Labels | B3: Sum of TOTAL INCOME
A4: BEVERAGE | B4: 1360
A5: DESSERT | B5: 6170
A6: MAIN COURSE | B6: 13220
A7: Grand Total | B7: 20750

Sheet Sheet4
A3: Row Labels | B3: Sum of TOTAL INCOME
A4: NORTH | B4: 7650
A5: SOUTH | B5: 4210
A6: WEST | B6: 8890
A7: Grand Total | B7: 20750

Sheet Sheet5
A3: Row Labels | B3: Sum of TOTAL INCOME
A4: BURGER | B4: 5920
A5: CAKE | B5: 4450
A6: COKE | B6: 1360
A7: PASTRY | B7: 1720
A8: PIZZA | B8: 7300
A9: Grand Total | B9: 20750

Sheet RAW DATA
A1: ORDER ID | B1: ORDER DATE | C1: COMPANY NAME | D1: CITY | E1: SALESPERSON | F1: REGION PRODUCT NAME | G1: PRODUCT | H1: CATEGORY | I1: UNIT PRICE | J1: QUANTITY | K1: TOTAL INCOME
A2: 101 | B2: =TODAY() -> 46317 | C2: TESLA | D2: PUNE | E2: AMIT | F2: WEST | G2: COKE | H2: =IF(G2="COKE","BEVERAGE",IF(G2="CAKE","DESSERT",IF(G2="PIZZA","MAIN COURSE",IF(G2="BURGER","MAIN COURSE",IF(G2="PASTRY","DESSERT",""))))) -> BEVERAGE | I2: =IF(G2="COKE",20,IF(G2="CAKE",50,IF(G2="PIZZA",100,IF(G2="BURGER",80,IF(G2="PASTRY",40))))) -> 20 | J2: 4 | K2: =I2*J2 -> 80
A3: 102 | B3: 45158 | C3: AMAZON | D3: HYDERABAD | E3: SUMIT | F3: SOUTH | G3: CAKE | H3: =IF(G3="COKE","BEVERAGE",IF(G3="CAKE","DESSERT",IF(G3="PIZZA","MAIN COURSE",IF(G3="BURGER","MAIN COURSE",IF(G3="PASTRY","DESSERT",""))))) -> DESSERT | I3: =IF(G3="COKE",20,IF(G3="CAKE",50,IF(G3="PIZZA",100,IF(G3="BURGER",80,IF(G3="PASTRY",40))))) -> 50 | J3: 3 | K3: =I3*J3 -> 150
A4: 103 | B4: 45097 | C4: FLIPKART | D4: MUMBAI | E4: AMAN | F4: WEST | G4: PIZZA | H4: =IF(G4="COKE","BEVERAGE",IF(G4="CAKE","DESSERT",IF(G4="PIZZA","MAIN COURSE",IF(G4="BURGER","MAIN COURSE",IF(G4="PASTRY","DESSERT",""))))) -> MAIN COURSE | I4: =IF(G4="COKE",20,IF(G4="CAKE",50,IF(G4="PIZZA",100,IF(G4="BURGER",80,IF(G4="PASTRY",40))))) -> 100 | J4: 4 | K4: =I4*J4 -> 400
A5: 104 | B5: 45064 | C5: UBER | D5: GURGAON | E5: SAM | F5: NORTH | G5: BURGER | H5: =IF(G5="COKE","BEVERAGE",IF(G5="CAKE","DESSERT",IF(G5="PIZZA","MAIN COURSE",IF(G5="BURGER","MAIN COURSE",IF(G5="PASTRY","DESSERT",""))))) -> MAIN COURSE | I5: =IF(G5="COKE",20,IF(G5="CAKE",50,IF(G5="PIZZA",100,IF(G5="BURGER",80,IF(G5="PASTRY",40))))) -> 80 | J5: 5 | K5: =I5*J5 -> 400
A6: 105 | B6: 45142 | C6: SHOPSY | D6: DELHI | E6: PRIYA | F6: NORTH | G6: PASTRY | H6: =IF(G6="COKE","BEVERAGE",IF(G6="CAKE","DESSERT",IF(G6="PIZZA","MAIN COURSE",IF(G6="BURGER","MAIN COURSE",IF(G6="PASTRY","DESSERT",""))))) -> DESSERT | I6: =IF(G6="COKE",20,IF(G6="CAKE",50,IF(G6="PIZZA",100,IF(G6="BURGER",80,IF(G6="PASTRY",40))))) -> 40 | J6: 5 | K6: =I6*J6 -> 200
A7: 106 | B7: 45150 | C7: TESLA | D7: NOIDA | E7: AMIT | F7: NORTH | G7: COKE | H7: =IF(G7="COKE","BEVERAGE",IF(G7="CAKE","DESSERT",IF(G7="PIZZA","MAIN COURSE",IF(G7="BURGER","MAIN COURSE",IF(G7="PASTRY","DESSERT",""))))) -> BEVERAGE | I7: =IF(G7="COKE",20,IF(G7="CAKE",50,IF(G7="PIZZA",100,IF(G7="BURGER",80,IF(G7="PASTRY",40))))) -> 20 | J7: 2 | K7: =I7*J7 -> 40
A8: 107 | B8: 45031 | C8: AMAZON | D8: PUNE | E8: SUMIT | F8: WEST | G8: CAKE | H8: =IF(G8="COKE","BEVERAGE",IF(G8="CAKE","DESSERT",IF(G8="PIZZA","MAIN COURSE",IF(G8="BURGER","MAIN COURSE",IF(G8="PASTRY","DESSERT",""))))) -> DESSERT | I8: =IF(G8="COKE",20,IF(G8="CAKE",50,IF(G8="PIZZA",100,IF(G8="BURGER",80,IF(G8="PASTRY",40))))) -> 50 | J8: 5 | K8: =I8*J8 -> 250
A9: 108 | B9: 45154 | C9: FLIPKART | D9: HYDERABAD | E9: AMAN | F9: SOUTH | G9: PIZZA | H9: =IF(G9="COKE","BEVERAGE",IF(G9="CAKE","DESSERT",IF(G9="PIZZA","MAIN COURSE",IF(G9="BURGER","MAIN COURSE",IF(G9="PASTRY","DESSERT",""))))) -> MAIN COURSE | I9: =IF(G9="COKE",20,IF(G9="CAKE",50,IF(G9="PIZZA",100,IF(G9="BURGER",80,IF(G9="PASTRY",40))))) -> 100 | J9: 5 | K9: =I9*J9 -> 500
A10: 109 | B10: 45060 | C10: UBER | D10: MUMBAI | E10: SAM | F10: WEST | G10: BURGER | H10: =IF(G10="COKE","BEVERAGE",IF(G10="CAKE","DESSERT",IF(G10="PIZZA","MAIN COURSE",IF(G10="BURGER","MAIN COURSE",IF(G10="PASTRY","DESSERT",""))))) -> MAIN COURSE | I10: =IF(G10="COKE",20,IF(G10="CAKE",50,IF(G10="PIZZA",100,IF(G10="BURGER",80,IF(G10="PASTRY",40))))) -> 80 | J10: 2 | K10: =I10*J10 -> 160
A11: 110 | B11: 45065 | C11: AMAZON | D11: GURGAON | E11: PRIYA | F11: NORTH | G11: CAKE | H11: =IF(G11="COKE","BEVERAGE",IF(G11="CAKE","DESSERT",IF(G11="PIZZA","MAIN COURSE",IF(G11="BURGER","MAIN COURSE",IF(G11="PASTRY","DESSERT",""))))) -> DESSERT | I11: =IF(G11="COKE",20,IF(G11="CAKE",50,IF(G11="PIZZA",100,IF(G11="BURGER",80,IF(G11="PASTRY",40))))) -> 50 | J11: 1 | K11: =I11*J11 -> 50
A12: 111 | B12: 45079 | C12: FLIPKART | D12: PUNE | E12: AMIT | F12: WEST | G12: PIZZA | H12: =IF(G12="COKE","BEVERAGE",IF(G12="CAKE","DESSERT",IF(G12="PIZZA","MAIN COURSE",IF(G12="BURGER","MAIN COURSE",IF(G12="PASTRY","DESSERT",""))))) -> MAIN COURSE | I12: =IF(G12="COKE",20,IF(G12="CAKE",50,IF(G12="PIZZA",100,IF(G12="BURGER",80,IF(G12="PASTRY",40))))) -> 100 | J12: 3 | K12: =I12*J12 -> 300
A13: 112 | B13: =TODAY() -> 46317 | C13: UBER | D13: HYDERABAD | E13: SUMIT | F13: SOUTH | G13: BURGER | H13: =IF(G13="COKE","BEVERAGE",IF(G13="CAKE","DESSERT",IF(G13="PIZZA","MAIN COURSE",IF(G13="BURGER","MAIN COURSE",IF(G13="PASTRY","DESSERT",""))))) -> MAIN COURSE | I13: =IF(G13="COKE",20,IF(G13="CAKE",50,IF(G13="PIZZA",100,IF(G13="BURGER",80,IF(G13="PASTRY",40))))) -> 80 | J13: 5 | K13: =I13*J13 -> 400
A14: 113 | B14: 45158 | C14: SHOPSY | D14: MUMBAI | E14: AMAN | F14: WEST | G14: PASTRY | H14: =IF(G14="COKE","BEVERAGE",IF(G14="CAKE","DESSERT",IF(G14="PIZZA","MAIN COURSE",IF(G14="BURGER","MAIN COURSE",IF(G14="PASTRY","DESSERT",""))))) -> DESSERT | I14: =IF(G14="COKE",20,IF(G14="CAKE",50,IF(G14="PIZZA",100,IF(G14="BURGER",80,IF(G14="PASTRY",40))))) -> 40 | J14: 2 | K14: =I14*J14 -> 80
A15: 114 | B15: 45097 | C15: TESLA | D15: GURGAON | E15: SAM | F15: NORTH | G15: COKE | H15: =IF(G15="COKE","BEVERAGE",IF(G15="CAKE","DESSERT",IF(G15="PIZZA","MAIN COURSE",IF(G15="BURGER","MAIN COURSE",IF(G15="PASTRY","DESSERT",""))))) -> BEVERAGE | I15: =IF(G15="COKE",20,IF(G15="CAKE",50,IF(G15="PIZZA",100,IF(G15="BURGER",80,IF(G15="PASTRY",40))))) -> 20 | J15: 4 | K15: =I15*J15 -> 80
A16: 115 | B16: 45064 | C16: AMAZON | D16: DELHI | E16: PRIYA | F16: NORTH | G16: COKE | H16: =IF(G16="COKE","BEVERAGE",IF(G16="CAKE","DESSERT",IF(G16="PIZZA","MAIN COURSE",IF(G16="BURGER","MAIN COURSE",IF(G16="PASTRY","DESSERT",""))))) -> BEVERAGE | I16: =IF(G16="COKE",20,IF(G16="CAKE",50,IF(G16="PIZZA",100,IF(G16="BURGER",80,IF(G16="PASTRY",40))))) -> 20 | J16: 3 | K16: =I16*J16 -> 60
A17: 116 | B17: 45142 | C17: FLIPKART | D17: NOIDA | E17: AMIT | F17: NORTH | G17: CAKE | H17: =IF(G17="COKE","BEVERAGE",IF(G17="CAKE","DESSERT",IF(G17="PIZZA","MAIN COURSE",IF(G17="BURGER","MAIN COURSE",IF(G17="PASTRY","DESSERT",""))))) -> DESSERT | I17: =IF(G17="COKE",20,IF(G17="CAKE",50,IF(G17="PIZZA",100,IF(G17="BURGER",80,IF(G17="PASTRY",40))))) -> 50 | J17: 3 | K17: =I17*J17 -> 150
A18: 117 | B18: 45150 | C18: UBER | D18: PUNE | E18: SUMIT | F18: WEST | G18: PIZZA | H18: =IF(G18="COKE","BEVERAGE",IF(G18="CAKE","DESSERT",IF(G18="PIZZA","MAIN COURSE",IF(G18="BURGER","MAIN COURSE",IF(G18="PASTRY","DESSERT",""))))) -> MAIN COURSE | I18: =IF(G18="COKE",20,IF(G18="CAKE",50,IF(G18="PIZZA",100,IF(G18="BURGER",80,IF(G18="PASTRY",40))))) -> 100 | J18: 3 | K18: =I18*J18 -> 300
A19: 118 | B19: 45031 | C19: SHOPSY | D19: HYDERABAD | E19: AMAN | F19: SOUTH | G19: BURGER | H19: =IF(G19="COKE","BEVERAGE",IF(G19="CAKE","DESSERT",IF(G19="PIZZA","MAIN COURSE",IF(G19="BURGER","MAIN COURSE",IF(G19="PASTRY","DESSERT",""))))) -> MAIN COURSE | I19: =IF(G19="COKE",20,IF(G19="CAKE",50,IF(G19="PIZZA",100,IF(G19="BURGER",80,IF(G19="PASTRY",40))))) -> 80 | J19: 1 | K19: =I19*J19 -> 80
A20: 119 | B20: 45064 | C20: TESLA | D20: MUMBAI | E20: SAM | F20: WEST | G20: PASTRY | H20: =IF(G20="COKE","BEVERAGE",IF(G20="CAKE","DESSERT",IF(G20="PIZZA","MAIN COURSE",IF(G20="BURGER","MAIN COURSE",IF(G20="PASTRY","DESSERT",""))))) -> DESSERT | I20: =IF(G20="COKE",20,IF(G20="CAKE",50,IF(G20="PIZZA",100,IF(G20="BURGER",80,IF(G20="PASTRY",40))))) -> 40 | J20: 4 | K20: =I20*J20 -> 160
A21: 120 | B21: 45142 | C21: AMAZON | D21: GURGAON | E21: SUMIT | F21: NORTH | G21: COKE | H21: =IF(G21="COKE","BEVERAGE",IF(G21="CAKE","DESSERT",IF(G21="PIZZA","MAIN COURSE",IF(G21="BURGER","MAIN COURSE",IF(G21="PASTRY","DESSERT",""))))) -> BEVERAGE | I21: =IF(G21="COKE",20,IF(G21="CAKE",50,IF(G21="PIZZA",100,IF(G21="BURGER",80,IF(G21="PASTRY",40))))) -> 20 | J21: 5 | K21: =I21*J21 -> 100
A22: 121 | B22: 45150 | C22: FLIPKART | D22: DELHI | E22: AMAN | F22: NORTH | G22: CAKE | H22: =IF(G22="COKE","BEVERAGE",IF(G22="CAKE","DESSERT",IF(G22="PIZZA","MAIN COURSE",IF(G22="BURGER","MAIN COURSE",IF(G22="PASTRY","DESSERT",""))))) -> DESSERT | I22: =IF(G22="COKE",20,IF(G22="CAKE",50,IF(G22="PIZZA",100,IF(G22="BURGER",80,IF(G22="PASTRY",40))))) -> 50 | J22: 4 | K22: =I22*J22 -> 200
A23: 122 | B23: 45031 | C23: UBER | D23: NOIDA | E23: SAM | F23: NORTH | G23: PIZZA | H23: =IF(G23="COKE","BEVERAGE",IF(G23="CAKE","DESSERT",IF(G23="PIZZA","MAIN COURSE",IF(G23="BURGER","MAIN COURSE",IF(G23="PASTRY","DESSERT",""))))) -> MAIN COURSE | I23: =IF(G23="COKE",20,IF(G23="CAKE",50,IF(G23="PIZZA",100,IF(G23="BURGER",80,IF(G23="PASTRY",40))))) -> 100 | J23: 1 | K23: =I23*J23 -> 100
A24: 123 | B24: 45154 | C24: FLIPKART | D24: PUNE | E24: PRIYA | F24: WEST | G24: BURGER | H24: =IF(G24="COKE","BEVERAGE",IF(G24="CAKE","DESSERT",IF(G24="PIZZA","MAIN COURSE",IF(G24="BURGER","MAIN COURSE",IF(G24="PASTRY","DESSERT",""))))) -> MAIN COURSE | I24: =IF(G24="COKE",20,IF(G24="CAKE",50,IF(G24="PIZZA",100,IF(G24="BURGER",80,IF(G24="PASTRY",40))))) -> 80 | J24: 2 | K24: =I24*J24 -> 160
A25: 124 | B25: 45060 | C25: UBER | D25: HYDERABAD | E25: AMIT | F25: SOUTH | G25: CAKE | H25: =IF(G25="COKE","BEVERAGE",IF(G25="CAKE","DESSERT",IF(G25="PIZZA","MAIN COURSE",IF(G25="BURGER","MAIN COURSE",IF(G25="PASTRY","DESSERT",""))))) -> DESSERT | I25: =IF(G25="COKE",20,IF(G25="CAKE",50,IF(G25="PIZZA",100,IF(G25="BURGER",80,IF(G25="PASTRY",40))))) -> 50 | J25: 3 | K25: =I25*J25 -> 150
... A27: 126 | B27: 45079 | C27: TESLA | D27: GURGAON | E27: AMAN | F27: NORTH | G27: BURGER | H27: =IF(G27="COKE","BEVERAGE",IF(G27="CAKE","DESSERT",IF(G27="PIZZA","MAIN COURSE",IF(G27="BURGER","MAIN COURSE",IF(G27="PASTRY","DESSERT",""))))) -> MAIN COURSE | I27: =IF(G27="COKE",20,IF(G27="CAKE",50,IF(G27="PIZZA",100,IF(G27="BURGER",80,IF(G27="PASTRY",40))))) -> 80 | J27: 3 | K27: =I27*J27 -> 240
A28: 127 | B28: =TODAY() -> 46317 | C28: AMAZON | D28: PUNE | E28: SAM | F28: WEST | G28: CAKE | H28: =IF(G28="COKE","BEVERAGE",IF(G28="CAKE","DESSERT",IF(G28="PIZZA","MAIN COURSE",IF(G28="BURGER","MAIN COURSE",IF(G28="PASTRY","DESSERT",""))))) -> DESSERT | I28: =IF(G28="COKE",20,IF(G28="CAKE",50,IF(G28="PIZZA",100,IF(G28="BURGER",80,IF(G28="PASTRY",40))))) -> 50 | J28: 2 | K28: =I28*J28 -> 100
A29: 128 | B29: 45158 | C29: FLIPKART | D29: HYDERABAD | E29: PRIYA | F29: SOUTH | G29: PIZZA | H29: =IF(G29="COKE","BEVERAGE",IF(G29="CAKE","DESSERT",IF(G29="PIZZA","MAIN COURSE",IF(G29="BURGER","MAIN COURSE",IF(G29="PASTRY","DESSERT",""))))) -> MAIN COURSE | I29: =IF(G29="COKE",20,IF(G29="CAKE",50,IF(G29="PIZZA",100,IF(G29="BURGER",80,IF(G29="PASTRY",40))))) -> 100 | J29: 4 | K29: =I29*J29 -> 400
A30: 129 | B30: 45097 | C30: UBER | D30: MUMBAI | E30: AMIT | F30: WEST | G30: BURGER | H30: =IF(G30="COKE","BEVERAGE",IF(G30="CAKE","DESSERT",IF(G30="PIZZA","MAIN COURSE",IF(G30="BURGER","MAIN COURSE",IF(G30="PASTRY","DESSERT",""))))) -> MAIN COURSE | I30: =IF(G30="COKE",20,IF(G30="CAKE",50,IF(G30="PIZZA",100,IF(G30="BURGER",80,IF(G30="PASTRY",40))))) -> 80 | J30: 3 | K30: =I30*J30 -> 240
A31: 130 | B31: 45064 | C31: AMAZON | D31: GURGAON | E31: SUMIT | F31: NORTH | G31: PASTRY | H31: =IF(G31="COKE","BEVERAGE",IF(G31="CAKE","DESSERT",IF(G31="PIZZA","MAIN COURSE",IF(G31="BURGER","MAIN COURSE",IF(G31="PASTRY","DESSERT",""))))) -> DESSERT | I31: =IF(G31="COKE",20,IF(G31="CAKE",50,IF(G31="PIZZA",100,IF(G31="BURGER",80,IF(G31="PASTRY",40))))) -> 40 | J31: 2 | K31: =I31*J31 -> 80
A32: 131 | B32: 45142 | C32: FLIPKART | D32: GURGAON | E32: AMAN | F32: NORTH | G32: COKE | H32: =IF(G32="COKE","BEVERAGE",IF(G32="CAKE","DESSERT",IF(G32="PIZZA","MAIN COURSE",IF(G32="BURGER","MAIN COURSE",IF(G32="PASTRY","DESSERT",""))))) -> BEVERAGE | I32: =IF(G32="COKE",20,IF(G32="CAKE",50,IF(G32="PIZZA",100,IF(G32="BURGER",80,IF(G32="PASTRY",40))))) -> 20 | J32: 2 | K32: =I32*J32 -> 40
A33: 132 | B33: 45150 | C33: UBER | D33: PUNE | E33: SAM | F33: WEST | G33: CAKE | H33: =IF(G33="COKE","BEVERAGE",IF(G33="CAKE","DESSERT",IF(G33="PIZZA","MAIN COURSE",IF(G33="BURGER","MAIN COURSE",IF(G33="PASTRY","DESSERT",""))))) -> DESSERT | I33: =IF(G33="COKE",20,IF(G33="CAKE",50,IF(G33="PIZZA",100,IF(G33="BURGER",80,IF(G33="PASTRY",40))))) -> 50 | J33: 4 | K33: =I33*J33 -> 200
A34: 133 | B34: 45031 | C34: SHOPSY | D34: HYDERABAD | E34: PRIYA | F34: SOUTH | G34: PIZZA | H34: =IF(G34="COKE","BEVERAGE",IF(G34="CAKE","DESSERT",IF(G34="PIZZA","MAIN COURSE",IF(G34="BURGER","MAIN COURSE",IF(G34="PASTRY","DESSERT",""))))) -> MAIN COURSE | I34: =IF(G34="COKE",20,IF(G34="CAKE",50,IF(G34="PIZZA",100,IF(G34="BURGER",80,IF(G34="PASTRY",40))))) -> 100 | J34: 3 | K34: =I34*J34 -> 300
A35: 134 | B35: 45064 | C35: TESLA | D35: MUMBAI | E35: AMIT | F35: WEST | G35: BURGER | H35: =IF(G35="COKE","BEVERAGE",IF(G35="CAKE","DESSERT",IF(G35="PIZZA","MAIN COURSE",IF(G35="BURGER","MAIN COURSE",IF(G35="PASTRY","DESSERT",""))))) -> MAIN COURSE | I35: =IF(G35="COKE",20,IF(G35="CAKE",50,IF(G35="PIZZA",100,IF(G35="BURGER",80,IF(G35="PASTRY",40))))) -> 80 | J35: 5 | K35: =I35*J35 -> 400
A36: 135 | B36: 45142 | C36: AMAZON | D36: GURGAON | E36: SUMIT | F36: NORTH | G36: CAKE | H36: =IF(G36="COKE","BEVERAGE",IF(G36="CAKE","DESSERT",IF(G36="PIZZA","MAIN COURSE",IF(G36="BURGER","MAIN COURSE",IF(G36="PASTRY","DESSERT",""))))) -> DESSERT | I36: =IF(G36="COKE",20,IF(G36="CAKE",50,IF(G36="PIZZA",100,IF(G36="BURGER",80,IF(G36="PASTRY",40))))) -> 50 | J36: 3 | K36: =I36*J36 -> 150
A37: 136 | B37: 45150 | C37: FLIPKART | D37: DELHI | E37: AMAN | F37: NORTH | G37: PIZZA | H37: =IF(G37="COKE","BEVERAGE",IF(G37="CAKE","DESSERT",IF(G37="PIZZA","MAIN COURSE",IF(G37="BURGER","MAIN COURSE",IF(G37="PASTRY","DESSERT",""))))) -> MAIN COURSE | I37: =IF(G37="COKE",20,IF(G37="CAKE",50,IF(G37="PIZZA",100,IF(G37="BURGER",80,IF(G37="PASTRY",40))))) -> 100 | J37: 2 | K37: =I37*J37 -> 200
A38: 137 | B38: 45031 | C38: FLIPKART | D38: NOIDA | E38: SAM | F38: NORTH | G38: BURGER | H38: =IF(G38="COKE","BEVERAGE",IF(G38="CAKE","DESSERT",IF(G38="PIZZA","MAIN COURSE",IF(G38="BURGER","MAIN COURSE",IF(G38="PASTRY","DESSERT",""))))) -> MAIN COURSE | I38: =IF(G38="COKE",20,IF(G38="CAKE",50,IF(G38="PIZZA",100,IF(G38="BURGER",80,IF(G38="PASTRY",40))))) -> 80 | J38: 4 | K38: =I38*J38 -> 320
A39: 138 | B39: 45154 | C39: UBER | D39: PUNE | E39: PRIYA | F39: WEST | G39: PASTRY | H39: =IF(G39="COKE","BEVERAGE",IF(G39="CAKE","DESSERT",IF(G39="PIZZA","MAIN COURSE",IF(G39="BURGER","MAIN COURSE",IF(G39="PASTRY","DESSERT",""))))) -> DESSERT | I39: =IF(G39="COKE",20,IF(G39="CAKE",50,IF(G39="PIZZA",100,IF(G39="BURGER",80,IF(G39="PASTRY",40))))) -> 40 | J39: 5 | K39: =I39*J39 -> 200
A40: 139 | B40: 45060 | C40: AMAZON | D40: HYDERABAD | E40: AMIT | F40: SOUTH | G40: COKE | H40: =IF(G40="COKE","BEVERAGE",IF(G40="CAKE","DESSERT",IF(G40="PIZZA","MAIN COURSE",IF(G40="BURGER","MAIN COURSE",IF(G40="PASTRY","DESSERT",""))))) -> BEVERAGE | I40: =IF(G40="COKE",20,IF(G40="CAKE",50,IF(G40="PIZZA",100,IF(G40="BURGER",80,IF(G40="PASTRY",40))))) -> 20 | J40: 2 | K40: =I40*J40 -> 40
... A42: 141 | B42: 45079 | C42: UBER | D42: GURGAON | E42: AMAN | F42: NORTH | G42: CAKE | H42: =IF(G42="COKE","BEVERAGE",IF(G42="CAKE","DESSERT",IF(G42="PIZZA","MAIN COURSE",IF(G42="BURGER","MAIN COURSE",IF(G42="PASTRY","DESSERT",""))))) -> DESSERT | I42: =IF(G42="COKE",20,IF(G42="CAKE",50,IF(G42="PIZZA",100,IF(G42="BURGER",80,IF(G42="PASTRY",40))))) -> 50 | J42: 3 | K42: =I42*J42 -> 150
...

Sheet RECEIPT
A1: ALL INDIA FOOD BAAZAR
A8: S.R. NO. | B8: ITEM NAME | C8: REGION | D8: PRICE | E8: QUANTITY | F8: AMOUNT | G8: DISCOUNT | H8: AMOUNT AFTER DISCOUNT
A10: 102 | B10: =_xlfn.IFNA(VLOOKUP(A10,'RAW DATA'!A1:K121,7,FALSE),"") -> CAKE | C10: =_xlfn.IFNA(VLOOKUP(A10,'RAW DATA'!A2:K121,6,FALSE),"") -> SOUTH | D10: =_xlfn.IFNA(VLOOKUP(RECEIPT!A10,'RAW DATA'!A2:K121,9,FALSE),"") -> 50 | E10: 5 | F10: =_xlfn.IFNA(D10*E10,"") -> 250 | G10: =IF(F10>=500,F10*10%,IF(F10>=250,F10*5%,"")) -> 12.5 | H10: =IFERROR(F10-G10,"") -> 237.5
A11: 103 | B11: =_xlfn.IFNA(VLOOKUP(A11,'RAW DATA'!A2:K122,7,FALSE),"") -> PIZZA | C11: =_xlfn.IFNA(VLOOKUP(A11,'RAW DATA'!A3:K122,6,FALSE),"") -> WEST | D11: =_xlfn.IFNA(VLOOKUP(RECEIPT!A11,'RAW DATA'!A3:K122,9,FALSE),"") -> 100 | E11: 8 | F11: =_xlfn.IFNA(D11*E11,"") -> 800 | G11: =IF(F11>=500,F11*10%,IF(F11>=250,F11*5%,"")) -> 80 | H11: =IFERROR(F11-G11,"") -> 720
A12: 202 | B12: =_xlfn.IFNA(VLOOKUP(A12,'RAW DATA'!A3:K123,7,FALSE),"") -> PIZZA | C12: =_xlfn.IFNA(VLOOKUP(A12,'RAW DATA'!A4:K123,6,FALSE),"") -> NORTH | D12: =_xlfn.IFNA(VLOOKUP(RECEIPT!A12,'RAW DATA'!A4:K123,9,FALSE),"") -> 100 | E12: 9 | F12: =_xlfn.IFNA(D12*E12,"") -> 900 | G12: =IF(F12>=500,F12*10%,IF(F12>=250,F12*5%,"")) -> 90 | H12: =IFERROR(F12-G12,"") -> 810
A13: 204 | B13: =_xlfn.IFNA(VLOOKUP(A13,'RAW DATA'!A4:K124,7,FALSE),"") -> PASTRY | C13: =_xlfn.IFNA(VLOOKUP(A13,'RAW DATA'!A5:K124,6,FALSE),"") -> WEST | D13: =_xlfn.IFNA(VLOOKUP(RECEIPT!A13,'RAW DATA'!A5:K124,9,FALSE),"") -> 40 | F13: =_xlfn.IFNA(D13*E13,"") -> 0 | G13: =IF(F13>=500,F13*10%,IF(F13>=250,F13*5%,"")) | H13: =IFERROR(F13-G13,"")
B14: =_xlfn.IFNA(VLOOKUP(A14,'RAW DATA'!A5:K125,7,FALSE),"") | C14: =_xlfn.IFNA(VLOOKUP(A14,'RAW DATA'!A6:K125,6,FALSE),"") | D14: =_xlfn.IFNA(VLOOKUP(RECEIPT!A14,'RAW DATA'!A6:K125,9,FALSE),"") | F14: =IFERROR(D14*E14,"") | H14: =IFERROR(F14-G14,"")
B15: =_xlfn.IFNA(VLOOKUP(A15,'RAW DATA'!A6:K126,7,FALSE),"") | C15: =_xlfn.IFNA(VLOOKUP(A15,'RAW DATA'!A7:K126,6,FALSE),"") | D15: =_xlfn.IFNA(VLOOKUP(RECEIPT!A15,'RAW DATA'!A7:K126,9,FALSE),"") | F15: =IFERROR(D15*E15,"") | H15: =IFERROR(F15-G15,"")
B16: =_xlfn.IFNA(VLOOKUP(A16,'RAW DATA'!A7:K127,7,FALSE),"") | C16: =_xlfn.IFNA(VLOOKUP(A16,'RAW DATA'!A8:K127,6,FALSE),"") | D16: =_xlfn.IFNA(VLOOKUP(RECEIPT!A16,'RAW DATA'!A8:K127,9,FALSE),"") | F16: =IFERROR(D16*E16,"") | H16: =IFERROR(F16-G16,"")
B17: =_xlfn.IFNA(VLOOKUP(A17,'RAW DATA'!A8:K128,7,FALSE),"") | C17: =_xlfn.IFNA(VLOOKUP(A17,'RAW DATA'!A9:K128,6,FALSE),"") | D17: =_xlfn.IFNA(VLOOKUP(RECEIPT!A17,'RAW DATA'!A9:K128,9,FALSE),"") | F17: =IFERROR(D17*E17,"") | H17: =IFERROR(F17-G17,"")
B18: =_xlfn.IFNA(VLOOKUP(A18,'RAW DATA'!A9:K129,7,FALSE),"") | C18: =_xlfn.IFNA(VLOOKUP(A18,'RAW DATA'!A10:K129,6,FALSE),"") | D18: =_xlfn.IFNA(VLOOKUP(RECEIPT!A18,'RAW DATA'!A10:K129,9,FALSE),"") | F18: =IFERROR(D18*E18,"") | H18: =IFERROR(F18-G18,"")
B19: =_xlfn.IFNA(VLOOKUP(A19,'RAW DATA'!A10:K130,7,FALSE),"") | C19: =_xlfn.IFNA(VLOOKUP(A19,'RAW DATA'!A11:K130,6,FALSE),"") | D19: =_xlfn.IFNA(VLOOKUP(RECEIPT!A19,'RAW DATA'!A11:K130,9,FALSE),"") | F19: =IFERROR(D19*E19,"") | H19: =IFERROR(F19-G19,"")
B20: =_xlfn.IFNA(VLOOKUP(A20,'RAW DATA'!A11:K131,7,FALSE),"") | C20: =_xlfn.IFNA(VLOOKUP(A20,'RAW DATA'!A12:K131,6,FALSE),"") | D20: =_xlfn.IFNA(VLOOKUP(RECEIPT!A20,'RAW DATA'!A12:K131,9,FALSE),"") | F20: =IFERROR(D20*E20,"") | H20: =IFERROR(F20-G20,"")
A21: GRAND TOTAL | H21: =SUM(H10:H20) -> 1767.5

Sheet DASHBOARD
